2025-05-13 22:52:22,895 - INFO - Starting sector portfolios generation for 2025-05-05
2025-05-13 22:52:25,593 - ERROR - Error fetching data: 'Adj Close'
2025-05-13 22:52:25,605 - ERROR - Error during sector portfolios generation
Traceback (most recent call last):
  File "C:\Users\kvs39\Desktop\validityBase\Dagster\dagster_env\Lib\site-packages\pandas\core\indexes\base.py", line 3805, in get_loc
    return self._engine.get_loc(casted_key)
           ^^^^^^^^^^^^^^^^^^^^^^^^^^^^^^^^
  File "index.pyx", line 167, in pandas._libs.index.IndexEngine.get_loc
  File "index.pyx", line 196, in pandas._libs.index.IndexEngine.get_loc
  File "pandas\\_libs\\hashtable_class_helper.pxi", line 7081, in pandas._libs.hashtable.PyObjectHashTable.get_item
  File "pandas\\_libs\\hashtable_class_helper.pxi", line 7089, in pandas._libs.hashtable.PyObjectHashTable.get_item
KeyError: 'Adj Close'

The above exception was the direct cause of the following exception:

Traceback (most recent call last):
  File "C:\Users\kvs39\Desktop\validityBase\Dagster\portfolio_spdrs\dagster_pipelines\assets\portfolio_asset.py", line 53, in sector_portfolios
    df_portfolios = produce_sector_portfolios(partition_date, logger=file_logger)
                    ^^^^^^^^^^^^^^^^^^^^^^^^^^^^^^^^^^^^^^^^^^^^^^^^^^^^^^^^^^^^^
  File "C:\Users\kvs39\Desktop\validityBase\Dagster\portfolio_spdrs\dagster_pipelines\assets\portfolio_producer.py", line 51, in produce_sector_portfolios
    data = yf.download(tickers, start=start_date, end=end_date)['Adj Close']
           ~~~~~~~~~~~~~~~~~~~~~~~~~~~~~~~~~~~~~~~~~~~~~~~~~~~~^^^^^^^^^^^^^
  File "C:\Users\kvs39\Desktop\validityBase\Dagster\dagster_env\Lib\site-packages\pandas\core\frame.py", line 4101, in __getitem__
    return self._getitem_multilevel(key)
           ^^^^^^^^^^^^^^^^^^^^^^^^^^^^^
  File "C:\Users\kvs39\Desktop\validityBase\Dagster\dagster_env\Lib\site-packages\pandas\core\frame.py", line 4159, in _getitem_multilevel
    loc = self.columns.get_loc(key)
          ^^^^^^^^^^^^^^^^^^^^^^^^^
  File "C:\Users\kvs39\Desktop\validityBase\Dagster\dagster_env\Lib\site-packages\pandas\core\indexes\multi.py", line 3040, in get_loc
    loc = self._get_level_indexer(key, level=0)
          ^^^^^^^^^^^^^^^^^^^^^^^^^^^^^^^^^^^^^
  File "C:\Users\kvs39\Desktop\validityBase\Dagster\dagster_env\Lib\site-packages\pandas\core\indexes\multi.py", line 3391, in _get_level_indexer
    idx = self._get_loc_single_level_index(level_index, key)
          ^^^^^^^^^^^^^^^^^^^^^^^^^^^^^^^^^^^^^^^^^^^^^^^^^^
  File "C:\Users\kvs39\Desktop\validityBase\Dagster\dagster_env\Lib\site-packages\pandas\core\indexes\multi.py", line 2980, in _get_loc_single_level_index
    return level_index.get_loc(key)
           ^^^^^^^^^^^^^^^^^^^^^^^^
  File "C:\Users\kvs39\Desktop\validityBase\Dagster\dagster_env\Lib\site-packages\pandas\core\indexes\base.py", line 3812, in get_loc
    raise KeyError(key) from err
KeyError: 'Adj Close'
