2025-05-13 23:04:30,264 - INFO - Starting sector portfolios generation for 2025-05-05
2025-05-13 23:04:30,952 - ERROR - Error during sector portfolios generation
Traceback (most recent call last):
  File "C:\Users\kvs39\Desktop\validityBase\Dagster\dagster_env\Lib\site-packages\pandas\core\indexes\base.py", line 3805, in get_loc
    return self._engine.get_loc(casted_key)
           ^^^^^^^^^^^^^^^^^^^^^^^^^^^^^^^^
  File "index.pyx", line 167, in pandas._libs.index.IndexEngine.get_loc
  File "index.pyx", line 196, in pandas._libs.index.IndexEngine.get_loc
  File "pandas\\_libs\\hashtable_class_helper.pxi", line 7081, in pandas._libs.hashtable.PyObjectHashTable.get_item
  File "pandas\\_libs\\hashtable_class_helper.pxi", line 7089, in pandas._libs.hashtable.PyObjectHashTable.get_item
KeyError: 'Adj Close'

The above exception was the direct cause of the following exception:

Traceback (most recent call last):
  File "C:\Users\kvs39\Desktop\validityBase\Dagster\portfolio_spdrs\dagster_pipelines\assets\portfolio_producer.py", line 63, in produce_sector_portfolios
    adj_close_data[ticker] = data[ticker]['Adj Close']
                             ~~~~~~~~~~~~^^^^^^^^^^^^^
  File "C:\Users\kvs39\Desktop\validityBase\Dagster\dagster_env\Lib\site-packages\pandas\core\frame.py", line 4102, in __getitem__
    indexer = self.columns.get_loc(key)
              ^^^^^^^^^^^^^^^^^^^^^^^^^
  File "C:\Users\kvs39\Desktop\validityBase\Dagster\dagster_env\Lib\site-packages\pandas\core\indexes\base.py", line 3812, in get_loc
    raise KeyError(key) from err
KeyError: 'Adj Close'

During handling of the above exception, another exception occurred:

Traceback (most recent call last):
  File "C:\Users\kvs39\Desktop\validityBase\Dagster\portfolio_spdrs\dagster_pipelines\assets\portfolio_asset.py", line 53, in sector_portfolios
    df_portfolios = produce_sector_portfolios(partition_date, logger=file_logger)
                    ^^^^^^^^^^^^^^^^^^^^^^^^^^^^^^^^^^^^^^^^^^^^^^^^^^^^^^^^^^^^^
  File "C:\Users\kvs39\Desktop\validityBase\Dagster\portfolio_spdrs\dagster_pipelines\assets\portfolio_producer.py", line 65, in produce_sector_portfolios
    raise KeyError(f"'Adj Close' not found for {ticker}. Check yf.download() settings or data availability.")
KeyError: "'Adj Close' not found for XLK. Check yf.download() settings or data availability."
